Watching for file changes with StatReloader
Watching for file changes with StatReloader
Error: That port is already in use.
Internal Server Error: /posts/
Traceback (most recent call last):
  File "/home/ubuntu/.cache/pypoetry/virtualenvs/toyproject-FnfcXmLS-py3.12/lib/python3.12/site-packages/django/db/backends/utils.py", line 105, in _execute
    return self.cursor.execute(sql, params)
           ^^^^^^^^^^^^^^^^^^^^^^^^^^^^^^^^
  File "/home/ubuntu/.cache/pypoetry/virtualenvs/toyproject-FnfcXmLS-py3.12/lib/python3.12/site-packages/django/db/backends/sqlite3/base.py", line 360, in execute
    return super().execute(query, params)
           ^^^^^^^^^^^^^^^^^^^^^^^^^^^^^^
sqlite3.OperationalError: no such table: posts_post

The above exception was the direct cause of the following exception:

Traceback (most recent call last):
  File "/home/ubuntu/.cache/pypoetry/virtualenvs/toyproject-FnfcXmLS-py3.12/lib/python3.12/site-packages/django/core/handlers/exception.py", line 55, in inner
    response = get_response(request)
               ^^^^^^^^^^^^^^^^^^^^^
  File "/home/ubuntu/.cache/pypoetry/virtualenvs/toyproject-FnfcXmLS-py3.12/lib/python3.12/site-packages/django/core/handlers/base.py", line 197, in _get_response
    response = wrapped_callback(request, *callback_args, **callback_kwargs)
               ^^^^^^^^^^^^^^^^^^^^^^^^^^^^^^^^^^^^^^^^^^^^^^^^^^^^^^^^^^^^
  File "/home/ubuntu/.cache/pypoetry/virtualenvs/toyproject-FnfcXmLS-py3.12/lib/python3.12/site-packages/django/views/decorators/http.py", line 64, in inner
    return func(request, *args, **kwargs)
           ^^^^^^^^^^^^^^^^^^^^^^^^^^^^^^
  File "/home/ubuntu/Chaeyeon-Lee/toyproject/posts/views.py", line 43, in post_list
    for post in post_list:
                ^^^^^^^^^
  File "/home/ubuntu/.cache/pypoetry/virtualenvs/toyproject-FnfcXmLS-py3.12/lib/python3.12/site-packages/django/db/models/query.py", line 384, in __iter__
    self._fetch_all()
  File "/home/ubuntu/.cache/pypoetry/virtualenvs/toyproject-FnfcXmLS-py3.12/lib/python3.12/site-packages/django/db/models/query.py", line 1935, in _fetch_all
    self._result_cache = list(self._iterable_class(self))
                         ^^^^^^^^^^^^^^^^^^^^^^^^^^^^^^^^
  File "/home/ubuntu/.cache/pypoetry/virtualenvs/toyproject-FnfcXmLS-py3.12/lib/python3.12/site-packages/django/db/models/query.py", line 91, in __iter__
    results = compiler.execute_sql(
              ^^^^^^^^^^^^^^^^^^^^^
  File "/home/ubuntu/.cache/pypoetry/virtualenvs/toyproject-FnfcXmLS-py3.12/lib/python3.12/site-packages/django/db/models/sql/compiler.py", line 1622, in execute_sql
    cursor.execute(sql, params)
  File "/home/ubuntu/.cache/pypoetry/virtualenvs/toyproject-FnfcXmLS-py3.12/lib/python3.12/site-packages/django/db/backends/utils.py", line 122, in execute
    return super().execute(sql, params)
           ^^^^^^^^^^^^^^^^^^^^^^^^^^^^
  File "/home/ubuntu/.cache/pypoetry/virtualenvs/toyproject-FnfcXmLS-py3.12/lib/python3.12/site-packages/django/db/backends/utils.py", line 79, in execute
    return self._execute_with_wrappers(
           ^^^^^^^^^^^^^^^^^^^^^^^^^^^^
  File "/home/ubuntu/.cache/pypoetry/virtualenvs/toyproject-FnfcXmLS-py3.12/lib/python3.12/site-packages/django/db/backends/utils.py", line 92, in _execute_with_wrappers
    return executor(sql, params, many, context)
           ^^^^^^^^^^^^^^^^^^^^^^^^^^^^^^^^^^^^
  File "/home/ubuntu/.cache/pypoetry/virtualenvs/toyproject-FnfcXmLS-py3.12/lib/python3.12/site-packages/django/db/backends/utils.py", line 100, in _execute
    with self.db.wrap_database_errors:
         ^^^^^^^^^^^^^^^^^^^^^^^^^^^^
  File "/home/ubuntu/.cache/pypoetry/virtualenvs/toyproject-FnfcXmLS-py3.12/lib/python3.12/site-packages/django/db/utils.py", line 91, in __exit__
    raise dj_exc_value.with_traceback(traceback) from exc_value
  File "/home/ubuntu/.cache/pypoetry/virtualenvs/toyproject-FnfcXmLS-py3.12/lib/python3.12/site-packages/django/db/backends/utils.py", line 105, in _execute
    return self.cursor.execute(sql, params)
           ^^^^^^^^^^^^^^^^^^^^^^^^^^^^^^^^
  File "/home/ubuntu/.cache/pypoetry/virtualenvs/toyproject-FnfcXmLS-py3.12/lib/python3.12/site-packages/django/db/backends/sqlite3/base.py", line 360, in execute
    return super().execute(query, params)
           ^^^^^^^^^^^^^^^^^^^^^^^^^^^^^^
django.db.utils.OperationalError: no such table: posts_post
[11/Apr/2025 07:25:55] "GET /posts/ HTTP/1.1" 500 131268
[11/Apr/2025 07:28:37] "GET /posts/ HTTP/1.1" 200 86
[11/Apr/2025 07:45:21] "POST /posts/ HTTP/1.1" 200 208
[11/Apr/2025 07:45:21] "GET /posts/ HTTP/1.1" 200 210
Watching for file changes with StatReloader
[11/Apr/2025 08:42:15] "GET /posts/ HTTP/1.1" 200 210
[11/Apr/2025 08:43:02] "POST /posts/ HTTP/1.1" 200 208
[11/Apr/2025 08:43:06] "GET /posts/ HTTP/1.1" 200 336
Internal Server Error: /posts
Traceback (most recent call last):
  File "/home/ubuntu/.cache/pypoetry/virtualenvs/toyproject-FnfcXmLS-py3.12/lib/python3.12/site-packages/django/core/handlers/exception.py", line 55, in inner
    response = get_response(request)
               ^^^^^^^^^^^^^^^^^^^^^
  File "/home/ubuntu/.cache/pypoetry/virtualenvs/toyproject-FnfcXmLS-py3.12/lib/python3.12/site-packages/django/utils/deprecation.py", line 122, in __call__
    response = self.process_response(request, response)
               ^^^^^^^^^^^^^^^^^^^^^^^^^^^^^^^^^^^^^^^^
  File "/home/ubuntu/.cache/pypoetry/virtualenvs/toyproject-FnfcXmLS-py3.12/lib/python3.12/site-packages/django/middleware/common.py", line 108, in process_response
    return self.response_redirect_class(self.get_full_path_with_slash(request))
                                        ^^^^^^^^^^^^^^^^^^^^^^^^^^^^^^^^^^^^^^
  File "/home/ubuntu/.cache/pypoetry/virtualenvs/toyproject-FnfcXmLS-py3.12/lib/python3.12/site-packages/django/middleware/common.py", line 87, in get_full_path_with_slash
    raise RuntimeError(
RuntimeError: You called this URL via POST, but the URL doesn't end in a slash and you have APPEND_SLASH set. Django can't redirect to the slash URL while maintaining POST data. Change your form to point to 3.39.180.27:8000/posts/ (note the trailing slash), or set APPEND_SLASH=False in your Django settings.
[11/Apr/2025 08:44:17] "POST /posts HTTP/1.1" 500 68145
[11/Apr/2025 08:44:27] "POST /posts/ HTTP/1.1" 200 208
[11/Apr/2025 08:44:51] "GET /posts/ HTTP/1.1" 200 462
[11/Apr/2025 08:45:20] "DELETE /posts/3 HTTP/1.1" 200 86
[11/Apr/2025 08:45:49] "DELETE /posts/3 HTTP/1.1" 200 74
Watching for file changes with StatReloader
Internal Server Error: /posts/
Traceback (most recent call last):
  File "/home/ubuntu/.cache/pypoetry/virtualenvs/toyproject-i2V2OP8o-py3.12/lib/python3.12/site-packages/django/db/backends/utils.py", line 105, in _execute
    return self.cursor.execute(sql, params)
           ^^^^^^^^^^^^^^^^^^^^^^^^^^^^^^^^
  File "/home/ubuntu/.cache/pypoetry/virtualenvs/toyproject-i2V2OP8o-py3.12/lib/python3.12/site-packages/django/db/backends/sqlite3/base.py", line 360, in execute
    return super().execute(query, params)
           ^^^^^^^^^^^^^^^^^^^^^^^^^^^^^^
sqlite3.OperationalError: no such table: posts_post

The above exception was the direct cause of the following exception:

Traceback (most recent call last):
  File "/home/ubuntu/.cache/pypoetry/virtualenvs/toyproject-i2V2OP8o-py3.12/lib/python3.12/site-packages/django/core/handlers/exception.py", line 55, in inner
    response = get_response(request)
               ^^^^^^^^^^^^^^^^^^^^^
  File "/home/ubuntu/.cache/pypoetry/virtualenvs/toyproject-i2V2OP8o-py3.12/lib/python3.12/site-packages/django/core/handlers/base.py", line 197, in _get_response
    response = wrapped_callback(request, *callback_args, **callback_kwargs)
               ^^^^^^^^^^^^^^^^^^^^^^^^^^^^^^^^^^^^^^^^^^^^^^^^^^^^^^^^^^^^
  File "/home/ubuntu/.cache/pypoetry/virtualenvs/toyproject-i2V2OP8o-py3.12/lib/python3.12/site-packages/django/views/decorators/http.py", line 64, in inner
    return func(request, *args, **kwargs)
           ^^^^^^^^^^^^^^^^^^^^^^^^^^^^^^
  File "/home/ubuntu/Chaeyeon-Lee/Toy-Project/toyproject/posts/views.py", line 43, in post_list
    for post in post_list:
                ^^^^^^^^^
  File "/home/ubuntu/.cache/pypoetry/virtualenvs/toyproject-i2V2OP8o-py3.12/lib/python3.12/site-packages/django/db/models/query.py", line 384, in __iter__
    self._fetch_all()
  File "/home/ubuntu/.cache/pypoetry/virtualenvs/toyproject-i2V2OP8o-py3.12/lib/python3.12/site-packages/django/db/models/query.py", line 1935, in _fetch_all
    self._result_cache = list(self._iterable_class(self))
                         ^^^^^^^^^^^^^^^^^^^^^^^^^^^^^^^^
  File "/home/ubuntu/.cache/pypoetry/virtualenvs/toyproject-i2V2OP8o-py3.12/lib/python3.12/site-packages/django/db/models/query.py", line 91, in __iter__
    results = compiler.execute_sql(
              ^^^^^^^^^^^^^^^^^^^^^
  File "/home/ubuntu/.cache/pypoetry/virtualenvs/toyproject-i2V2OP8o-py3.12/lib/python3.12/site-packages/django/db/models/sql/compiler.py", line 1622, in execute_sql
    cursor.execute(sql, params)
  File "/home/ubuntu/.cache/pypoetry/virtualenvs/toyproject-i2V2OP8o-py3.12/lib/python3.12/site-packages/django/db/backends/utils.py", line 122, in execute
    return super().execute(sql, params)
           ^^^^^^^^^^^^^^^^^^^^^^^^^^^^
  File "/home/ubuntu/.cache/pypoetry/virtualenvs/toyproject-i2V2OP8o-py3.12/lib/python3.12/site-packages/django/db/backends/utils.py", line 79, in execute
    return self._execute_with_wrappers(
           ^^^^^^^^^^^^^^^^^^^^^^^^^^^^
  File "/home/ubuntu/.cache/pypoetry/virtualenvs/toyproject-i2V2OP8o-py3.12/lib/python3.12/site-packages/django/db/backends/utils.py", line 92, in _execute_with_wrappers
    return executor(sql, params, many, context)
           ^^^^^^^^^^^^^^^^^^^^^^^^^^^^^^^^^^^^
  File "/home/ubuntu/.cache/pypoetry/virtualenvs/toyproject-i2V2OP8o-py3.12/lib/python3.12/site-packages/django/db/backends/utils.py", line 100, in _execute
    with self.db.wrap_database_errors:
         ^^^^^^^^^^^^^^^^^^^^^^^^^^^^
  File "/home/ubuntu/.cache/pypoetry/virtualenvs/toyproject-i2V2OP8o-py3.12/lib/python3.12/site-packages/django/db/utils.py", line 91, in __exit__
    raise dj_exc_value.with_traceback(traceback) from exc_value
  File "/home/ubuntu/.cache/pypoetry/virtualenvs/toyproject-i2V2OP8o-py3.12/lib/python3.12/site-packages/django/db/backends/utils.py", line 105, in _execute
    return self.cursor.execute(sql, params)
           ^^^^^^^^^^^^^^^^^^^^^^^^^^^^^^^^
  File "/home/ubuntu/.cache/pypoetry/virtualenvs/toyproject-i2V2OP8o-py3.12/lib/python3.12/site-packages/django/db/backends/sqlite3/base.py", line 360, in execute
    return super().execute(query, params)
           ^^^^^^^^^^^^^^^^^^^^^^^^^^^^^^
django.db.utils.OperationalError: no such table: posts_post
[11/Apr/2025 19:30:12] "GET /posts/ HTTP/1.1" 500 131416
Internal Server Error: /posts/
Traceback (most recent call last):
  File "/home/ubuntu/.cache/pypoetry/virtualenvs/toyproject-i2V2OP8o-py3.12/lib/python3.12/site-packages/django/db/backends/utils.py", line 105, in _execute
    return self.cursor.execute(sql, params)
           ^^^^^^^^^^^^^^^^^^^^^^^^^^^^^^^^
  File "/home/ubuntu/.cache/pypoetry/virtualenvs/toyproject-i2V2OP8o-py3.12/lib/python3.12/site-packages/django/db/backends/sqlite3/base.py", line 360, in execute
    return super().execute(query, params)
           ^^^^^^^^^^^^^^^^^^^^^^^^^^^^^^
sqlite3.OperationalError: no such table: posts_post

The above exception was the direct cause of the following exception:

Traceback (most recent call last):
  File "/home/ubuntu/.cache/pypoetry/virtualenvs/toyproject-i2V2OP8o-py3.12/lib/python3.12/site-packages/django/core/handlers/exception.py", line 55, in inner
    response = get_response(request)
               ^^^^^^^^^^^^^^^^^^^^^
  File "/home/ubuntu/.cache/pypoetry/virtualenvs/toyproject-i2V2OP8o-py3.12/lib/python3.12/site-packages/django/core/handlers/base.py", line 197, in _get_response
    response = wrapped_callback(request, *callback_args, **callback_kwargs)
               ^^^^^^^^^^^^^^^^^^^^^^^^^^^^^^^^^^^^^^^^^^^^^^^^^^^^^^^^^^^^
  File "/home/ubuntu/.cache/pypoetry/virtualenvs/toyproject-i2V2OP8o-py3.12/lib/python3.12/site-packages/django/views/decorators/http.py", line 64, in inner
    return func(request, *args, **kwargs)
           ^^^^^^^^^^^^^^^^^^^^^^^^^^^^^^
  File "/home/ubuntu/Chaeyeon-Lee/Toy-Project/toyproject/posts/views.py", line 43, in post_list
    for post in post_list:
                ^^^^^^^^^
  File "/home/ubuntu/.cache/pypoetry/virtualenvs/toyproject-i2V2OP8o-py3.12/lib/python3.12/site-packages/django/db/models/query.py", line 384, in __iter__
    self._fetch_all()
  File "/home/ubuntu/.cache/pypoetry/virtualenvs/toyproject-i2V2OP8o-py3.12/lib/python3.12/site-packages/django/db/models/query.py", line 1935, in _fetch_all
    self._result_cache = list(self._iterable_class(self))
                         ^^^^^^^^^^^^^^^^^^^^^^^^^^^^^^^^
  File "/home/ubuntu/.cache/pypoetry/virtualenvs/toyproject-i2V2OP8o-py3.12/lib/python3.12/site-packages/django/db/models/query.py", line 91, in __iter__
    results = compiler.execute_sql(
              ^^^^^^^^^^^^^^^^^^^^^
  File "/home/ubuntu/.cache/pypoetry/virtualenvs/toyproject-i2V2OP8o-py3.12/lib/python3.12/site-packages/django/db/models/sql/compiler.py", line 1622, in execute_sql
    cursor.execute(sql, params)
  File "/home/ubuntu/.cache/pypoetry/virtualenvs/toyproject-i2V2OP8o-py3.12/lib/python3.12/site-packages/django/db/backends/utils.py", line 122, in execute
    return super().execute(sql, params)
           ^^^^^^^^^^^^^^^^^^^^^^^^^^^^
  File "/home/ubuntu/.cache/pypoetry/virtualenvs/toyproject-i2V2OP8o-py3.12/lib/python3.12/site-packages/django/db/backends/utils.py", line 79, in execute
    return self._execute_with_wrappers(
           ^^^^^^^^^^^^^^^^^^^^^^^^^^^^
  File "/home/ubuntu/.cache/pypoetry/virtualenvs/toyproject-i2V2OP8o-py3.12/lib/python3.12/site-packages/django/db/backends/utils.py", line 92, in _execute_with_wrappers
    return executor(sql, params, many, context)
           ^^^^^^^^^^^^^^^^^^^^^^^^^^^^^^^^^^^^
  File "/home/ubuntu/.cache/pypoetry/virtualenvs/toyproject-i2V2OP8o-py3.12/lib/python3.12/site-packages/django/db/backends/utils.py", line 100, in _execute
    with self.db.wrap_database_errors:
         ^^^^^^^^^^^^^^^^^^^^^^^^^^^^
  File "/home/ubuntu/.cache/pypoetry/virtualenvs/toyproject-i2V2OP8o-py3.12/lib/python3.12/site-packages/django/db/utils.py", line 91, in __exit__
    raise dj_exc_value.with_traceback(traceback) from exc_value
  File "/home/ubuntu/.cache/pypoetry/virtualenvs/toyproject-i2V2OP8o-py3.12/lib/python3.12/site-packages/django/db/backends/utils.py", line 105, in _execute
    return self.cursor.execute(sql, params)
           ^^^^^^^^^^^^^^^^^^^^^^^^^^^^^^^^
  File "/home/ubuntu/.cache/pypoetry/virtualenvs/toyproject-i2V2OP8o-py3.12/lib/python3.12/site-packages/django/db/backends/sqlite3/base.py", line 360, in execute
    return super().execute(query, params)
           ^^^^^^^^^^^^^^^^^^^^^^^^^^^^^^
django.db.utils.OperationalError: no such table: posts_post
[11/Apr/2025 19:31:28] "GET /posts/ HTTP/1.1" 500 131416
Watching for file changes with StatReloader
[11/Apr/2025 19:34:26] "GET /posts/ HTTP/1.1" 200 86
[11/Apr/2025 19:35:28] "POST /posts/ HTTP/1.1" 200 208
[11/Apr/2025 19:35:50] "POST /posts/ HTTP/1.1" 200 208
[11/Apr/2025 19:36:00] "POST /posts/ HTTP/1.1" 200 208
[11/Apr/2025 19:36:05] "GET /posts/ HTTP/1.1" 200 462
[11/Apr/2025 19:36:17] "DELETE /posts/1 HTTP/1.1" 200 86
[11/Apr/2025 19:36:24] "DELETE /posts/1 HTTP/1.1" 200 74
[11/Apr/2025 19:36:30] "GET /posts/ HTTP/1.1" 200 336
[11/Apr/2025 19:36:58] "GET /posts/ HTTP/1.1" 200 336
[11/Apr/2025 19:37:37] "POST /posts/ HTTP/1.1" 200 208
[11/Apr/2025 19:38:11] "POST /posts/ HTTP/1.1" 200 208
[11/Apr/2025 19:38:15] "GET /posts/ HTTP/1.1" 200 588
[11/Apr/2025 19:39:30] "GET /posts/ HTTP/1.1" 200 588
[11/Apr/2025 19:40:12] "DELETE /posts/4 HTTP/1.1" 200 74
[11/Apr/2025 19:40:26] "GET /posts/ HTTP/1.1" 200 462
Watching for file changes with StatReloader
[12/Apr/2025 04:40:11] "GET /posts/ HTTP/1.1" 200 462
[12/Apr/2025 04:44:11] "GET /posts/ HTTP/1.1" 200 462
[12/Apr/2025 04:44:26] "DELETE /posts/5 HTTP/1.1" 200 74
[12/Apr/2025 04:48:09,969] - Broken pipe from ('39.118.91.170', 51965)
[12/Apr/2025 04:48:09,969] - Broken pipe from ('39.118.91.170', 51942)
[12/Apr/2025 04:52:12] "GET /posts/ HTTP/1.1" 200 336
[12/Apr/2025 07:11:29] code 400, message Bad HTTP/0.9 request type ('\x16\x03\x03\x01¤\x01\x00\x01')
[12/Apr/2025 07:11:29] You're accessing the development server over HTTPS, but it only supports HTTP.
Not Found: /
[12/Apr/2025 07:11:32] "GET / HTTP/1.1" 404 2308
[12/Apr/2025 07:21:14] "GET /posts/ HTTP/1.1" 200 336
Not Found: /favicon.ico
[12/Apr/2025 07:23:59] "GET /favicon.ico HTTP/1.1" 404 2359
[12/Apr/2025 07:24:27,391] - Broken pipe from ('39.118.91.170', 52569)
Not Found: /
[12/Apr/2025 07:35:03] "GET / HTTP/1.1" 404 2308
Not Found: /favicon.ico
[12/Apr/2025 07:35:56] "GET /favicon.ico HTTP/1.1" 404 2359
Not Found: /http:/api.ipify.org/
[12/Apr/2025 07:36:19] "GET http://api.ipify.org/?format=json HTTP/1.1" 404 1873
Not Found: /www.shadowserver.org:443
[12/Apr/2025 07:36:42] "CONNECT www.shadowserver.org:443 HTTP/1.1" 404 1882
[12/Apr/2025 10:33:03] "GET /posts/ HTTP/1.1" 200 336
[12/Apr/2025 10:33:33] "DELETE /posts/2 HTTP/1.1" 200 86
Not Found: /
[12/Apr/2025 10:35:43] "GET / HTTP/1.1" 404 2303
Not Found: /
[12/Apr/2025 10:35:43] "GET / HTTP/1.1" 404 2303
Not Found: /
[12/Apr/2025 10:35:43] "GET / HTTP/1.1" 404 2303
Not Found: /
[12/Apr/2025 10:35:59] "GET / HTTP/1.1" 404 2303
[12/Apr/2025 10:36:00] "GET /posts/ HTTP/1.1" 200 336
[12/Apr/2025 10:36:11] "GET /posts/ HTTP/1.1" 200 336
Not Found: /
[12/Apr/2025 10:36:25] "GET / HTTP/1.1" 404 2308
Not Found: /
[12/Apr/2025 10:36:33] "GET / HTTP/1.1" 404 2308
Not Found: /favicon.ico
[12/Apr/2025 10:36:33] "GET /favicon.ico HTTP/1.1" 404 2359
Not Found: /
[12/Apr/2025 10:37:03] "GET / HTTP/1.1" 404 2308
[12/Apr/2025 10:40:06] "GET /posts/ HTTP/1.1" 200 336
[12/Apr/2025 10:40:10] "GET /posts/ HTTP/1.1" 200 336
[12/Apr/2025 10:40:17] "OPTIONS /posts/ HTTP/1.1" 200 0
Not Found: /
[12/Apr/2025 10:40:35] "GET / HTTP/1.1" 404 2308
Not Found: /
[12/Apr/2025 10:42:51] "GET / HTTP/1.1" 404 2308
Not Found: /
[12/Apr/2025 10:42:53] "GET / HTTP/1.1" 404 2308
Not Found: /
[12/Apr/2025 10:43:52] "GET / HTTP/1.1" 404 2303
Not Found: /
[12/Apr/2025 10:43:52] "GET / HTTP/1.1" 404 2303
[12/Apr/2025 10:44:17] "GET /posts/ HTTP/1.1" 200 336
[12/Apr/2025 10:44:17] "GET /posts/ HTTP/1.1" 200 336
[12/Apr/2025 10:44:20] "GET /posts/ HTTP/1.1" 200 336
[12/Apr/2025 10:44:27] "OPTIONS /posts/ HTTP/1.1" 200 0
[12/Apr/2025 10:44:43] "GET /posts/ HTTP/1.1" 200 336
[12/Apr/2025 10:45:48] "GET /posts/ HTTP/1.1" 200 336
[12/Apr/2025 10:45:48] "GET /posts/ HTTP/1.1" 200 336
[12/Apr/2025 10:52:25] "GET /posts/ HTTP/1.1" 200 336
[12/Apr/2025 10:52:57] "GET /posts/ HTTP/1.1" 200 336
[12/Apr/2025 11:02:50] "OPTIONS /posts/ HTTP/1.1" 200 0
[12/Apr/2025 11:02:50] "OPTIONS /posts/ HTTP/1.1" 200 0
[12/Apr/2025 11:02:50] "OPTIONS /posts/ HTTP/1.1" 200 0
[12/Apr/2025 11:02:50] "OPTIONS /posts/ HTTP/1.1" 200 0
[12/Apr/2025 11:02:50] "OPTIONS /posts/ HTTP/1.1" 200 0
[12/Apr/2025 11:02:50] "OPTIONS /posts/ HTTP/1.1" 200 0
Watching for file changes with StatReloader
Performing system checks...

System check identified no issues (0 silenced).
April 12, 2025 - 11:33:19
Django version 5.2, using settings 'config.settings'
Starting development server at http://0.0.0.0:8000/
Quit the server with CONTROL-C.

WARNING: This is a development server. Do not use it in a production setting. Use a production WSGI or ASGI server instead.
For more information on production servers see: https://docs.djangoproject.com/en/5.2/howto/deployment/
[12/Apr/2025 11:34:39] "GET /posts/ HTTP/1.1" 200 336
[12/Apr/2025 11:37:22] "GET /posts/ HTTP/1.1" 200 336
[12/Apr/2025 11:37:29] "OPTIONS /posts/ HTTP/1.1" 200 0
[12/Apr/2025 11:37:30] "POST /posts/ HTTP/1.1" 200 173
[12/Apr/2025 11:37:31] "POST /posts/ HTTP/1.1" 200 173
[12/Apr/2025 11:37:36] "GET /posts/ HTTP/1.1" 200 518
[12/Apr/2025 11:37:37] "GET /posts/ HTTP/1.1" 200 518
[12/Apr/2025 11:39:01] "GET /posts/ HTTP/1.1" 200 518
[12/Apr/2025 11:39:07] "GET /posts/ HTTP/1.1" 200 518
[12/Apr/2025 11:39:26] "OPTIONS /posts/ HTTP/1.1" 200 0
[12/Apr/2025 11:39:27] "POST /posts/ HTTP/1.1" 200 190
[12/Apr/2025 11:39:30] "POST /posts/ HTTP/1.1" 200 190
[12/Apr/2025 11:39:30] "POST /posts/ HTTP/1.1" 200 191
[12/Apr/2025 11:39:31] "POST /posts/ HTTP/1.1" 200 191
[12/Apr/2025 11:39:31] "POST /posts/ HTTP/1.1" 200 191
[12/Apr/2025 11:39:31] "POST /posts/ HTTP/1.1" 200 191
[12/Apr/2025 11:39:39] "POST /posts/ HTTP/1.1" 200 191
[12/Apr/2025 11:39:53] "GET /posts/ HTTP/1.1" 200 1279
[12/Apr/2025 11:40:49] "POST /posts/ HTTP/1.1" 200 179
[12/Apr/2025 11:41:22] "GET /posts/ HTTP/1.1" 200 1376
[12/Apr/2025 11:44:19] "GET /posts/ HTTP/1.1" 200 1376
[12/Apr/2025 11:46:29] "GET /posts/ HTTP/1.1" 200 1376
[12/Apr/2025 11:46:30] "GET /posts/ HTTP/1.1" 200 1376
[12/Apr/2025 11:46:36] "GET /posts/ HTTP/1.1" 200 1376
[12/Apr/2025 11:46:44] "OPTIONS /posts/15 HTTP/1.1" 200 0
[12/Apr/2025 11:46:45] "DELETE /posts/15 HTTP/1.1" 200 74
[12/Apr/2025 11:46:49] "OPTIONS /posts/14 HTTP/1.1" 200 0
[12/Apr/2025 11:46:50] "DELETE /posts/14 HTTP/1.1" 200 86
Not Found: /robots.txt
[12/Apr/2025 11:46:54] "GET /robots.txt HTTP/1.1" 404 2351
[12/Apr/2025 11:46:58] "DELETE /posts/14 HTTP/1.1" 200 74
Not Found: /
[12/Apr/2025 11:46:58] "GET / HTTP/1.1" 404 2303
Not Found: /
[12/Apr/2025 11:47:04] "GET / HTTP/1.1" 404 2308
[12/Apr/2025 11:47:30] "OPTIONS /posts/2 HTTP/1.1" 200 0
[12/Apr/2025 11:47:30] "DELETE /posts/2 HTTP/1.1" 200 86
[12/Apr/2025 11:47:36] "DELETE /posts/2 HTTP/1.1" 200 86
[12/Apr/2025 11:47:40] "DELETE /posts/2 HTTP/1.1" 200 86
[12/Apr/2025 11:48:32] "DELETE /posts/2 HTTP/1.1" 200 86
[12/Apr/2025 11:48:39] "OPTIONS /posts/13 HTTP/1.1" 200 0
[12/Apr/2025 11:48:40] "DELETE /posts/13 HTTP/1.1" 200 86
[12/Apr/2025 11:48:45] "DELETE /posts/13 HTTP/1.1" 200 74
[12/Apr/2025 11:48:49] "OPTIONS /posts/12 HTTP/1.1" 200 0
[12/Apr/2025 11:48:50] "DELETE /posts/12 HTTP/1.1" 200 74
[12/Apr/2025 11:48:54] "OPTIONS /posts/11 HTTP/1.1" 200 0
[12/Apr/2025 11:48:55] "DELETE /posts/11 HTTP/1.1" 200 74
[12/Apr/2025 11:48:59] "OPTIONS /posts/10 HTTP/1.1" 200 0
[12/Apr/2025 11:49:00] "DELETE /posts/10 HTTP/1.1" 200 86
[12/Apr/2025 11:49:05] "DELETE /posts/10 HTTP/1.1" 200 86
[12/Apr/2025 11:49:10] "DELETE /posts/10 HTTP/1.1" 200 86
[12/Apr/2025 11:49:17] "OPTIONS /posts/6 HTTP/1.1" 200 0
[12/Apr/2025 11:49:18] "DELETE /posts/6 HTTP/1.1" 200 74
[12/Apr/2025 11:49:22] "OPTIONS /posts/7 HTTP/1.1" 200 0
[12/Apr/2025 11:49:23] "DELETE /posts/7 HTTP/1.1" 200 74
[12/Apr/2025 11:49:30] "OPTIONS /posts/8 HTTP/1.1" 200 0
[12/Apr/2025 11:49:30] "DELETE /posts/8 HTTP/1.1" 200 86
[12/Apr/2025 11:49:38] "DELETE /posts/8 HTTP/1.1" 200 86
[12/Apr/2025 11:49:42] "DELETE /posts/8 HTTP/1.1" 200 74
[12/Apr/2025 11:49:48] "OPTIONS /posts/9 HTTP/1.1" 200 0
[12/Apr/2025 11:49:49] "DELETE /posts/9 HTTP/1.1" 200 74
[12/Apr/2025 11:49:54] "DELETE /posts/10 HTTP/1.1" 200 74
[12/Apr/2025 11:50:01] "GET /posts/ HTTP/1.1" 200 336
[12/Apr/2025 11:50:01] "GET /posts/ HTTP/1.1" 200 336
[12/Apr/2025 11:50:20] "POST /posts/ HTTP/1.1" 200 215
[12/Apr/2025 11:50:21] "DELETE /posts/2 HTTP/1.1" 200 74
[12/Apr/2025 11:50:27] "GET /posts/ HTTP/1.1" 200 343
[12/Apr/2025 11:50:45] "GET /posts/ HTTP/1.1" 200 343
[12/Apr/2025 11:50:45] "GET /posts/ HTTP/1.1" 200 343
[12/Apr/2025 11:50:53] "OPTIONS /posts/3 HTTP/1.1" 200 0
[12/Apr/2025 11:50:54] "DELETE /posts/3 HTTP/1.1" 200 86
[12/Apr/2025 11:51:20] "OPTIONS /posts/16 HTTP/1.1" 200 0
[12/Apr/2025 11:51:20] "DELETE /posts/16 HTTP/1.1" 200 74
Method Not Allowed (GET): /posts/3
[12/Apr/2025 11:51:27] "GET /posts/3 HTTP/1.1" 405 0
[12/Apr/2025 11:51:30] "GET /posts/ HTTP/1.1" 200 210
[12/Apr/2025 11:51:36] "DELETE /posts/3 HTTP/1.1" 200 74
[12/Apr/2025 11:51:40] "GET /posts/ HTTP/1.1" 200 86
[12/Apr/2025 11:51:53] "GET /posts/ HTTP/1.1" 200 86
[12/Apr/2025 11:52:12] "GET /posts/ HTTP/1.1" 200 86
[12/Apr/2025 11:52:17] "GET /posts/ HTTP/1.1" 200 86
[12/Apr/2025 11:52:33] "POST /posts/ HTTP/1.1" 200 257
[12/Apr/2025 11:54:48] "GET /posts/ HTTP/1.1" 200 259
[12/Apr/2025 11:54:51] "GET /posts/ HTTP/1.1" 200 259
[12/Apr/2025 11:55:02] "POST /posts/ HTTP/1.1" 200 219
[12/Apr/2025 11:55:16] "OPTIONS /posts/18 HTTP/1.1" 200 0
[12/Apr/2025 11:55:17] "DELETE /posts/18 HTTP/1.1" 200 74
[12/Apr/2025 11:55:51] "GET /posts/ HTTP/1.1" 200 259
[12/Apr/2025 11:55:51] "GET /posts/ HTTP/1.1" 200 259
[12/Apr/2025 11:55:52] "GET /posts/ HTTP/1.1" 200 259
[12/Apr/2025 11:55:52] "GET /posts/ HTTP/1.1" 200 259
[12/Apr/2025 11:56:39] "GET /posts/ HTTP/1.1" 200 259
[12/Apr/2025 11:59:57] "GET /posts/ HTTP/1.1" 200 259
[12/Apr/2025 12:00:45] "GET /posts/ HTTP/1.1" 200 259
[12/Apr/2025 12:01:30] "GET /posts/ HTTP/1.1" 200 259
[12/Apr/2025 12:01:43] "GET /posts/ HTTP/1.1" 200 259
[12/Apr/2025 12:01:43] "GET /posts/ HTTP/1.1" 200 259
[12/Apr/2025 12:01:44] "GET /posts/ HTTP/1.1" 200 259
[12/Apr/2025 12:01:44] "GET /posts/ HTTP/1.1" 200 259
[12/Apr/2025 12:01:53] "GET /posts/ HTTP/1.1" 200 259
[12/Apr/2025 12:01:59] "GET /posts/ HTTP/1.1" 200 259
[12/Apr/2025 12:02:04] "GET /posts/ HTTP/1.1" 200 259
[12/Apr/2025 12:02:16] "GET /posts/ HTTP/1.1" 200 259
[12/Apr/2025 12:02:43] "GET /posts/ HTTP/1.1" 200 259
[12/Apr/2025 12:04:27] "GET /posts/ HTTP/1.1" 200 259
[12/Apr/2025 12:04:28] "GET /posts/ HTTP/1.1" 200 259
[12/Apr/2025 12:06:39] "POST /posts/ HTTP/1.1" 200 221
[12/Apr/2025 12:06:49] "OPTIONS /posts/19 HTTP/1.1" 200 0
[12/Apr/2025 12:06:50] "DELETE /posts/19 HTTP/1.1" 200 74
[12/Apr/2025 12:07:46] "GET /posts/ HTTP/1.1" 200 259
[12/Apr/2025 12:26:11] "GET /posts/ HTTP/1.1" 200 259
[12/Apr/2025 12:26:41] "GET /posts/ HTTP/1.1" 200 259
Watching for file changes with StatReloader
Performing system checks...

System check identified no issues (0 silenced).
April 12, 2025 - 12:32:30
Django version 5.2, using settings 'config.settings'
Starting development server at http://0.0.0.0:8000/
Quit the server with CONTROL-C.

WARNING: This is a development server. Do not use it in a production setting. Use a production WSGI or ASGI server instead.
For more information on production servers see: https://docs.djangoproject.com/en/5.2/howto/deployment/
[12/Apr/2025 12:32:36] "GET /posts/ HTTP/1.1" 200 259
[12/Apr/2025 12:33:15] "GET /posts/ HTTP/1.1" 200 259
Watching for file changes with StatReloader
Performing system checks...

System check identified no issues (0 silenced).
April 12, 2025 - 12:54:39
Django version 5.2, using settings 'config.settings'
Starting development server at http://0.0.0.0:8000/
Quit the server with CONTROL-C.

WARNING: This is a development server. Do not use it in a production setting. Use a production WSGI or ASGI server instead.
For more information on production servers see: https://docs.djangoproject.com/en/5.2/howto/deployment/
[12/Apr/2025 12:55:02] "GET /posts/ HTTP/1.1" 200 259
[12/Apr/2025 12:55:15] "DELETE /posts/17 HTTP/1.1" 200 86
[12/Apr/2025 12:57:49] code 400, message Bad request version ('À\x14À')
[12/Apr/2025 12:57:49] You're accessing the development server over HTTPS, but it only supports HTTP.
[12/Apr/2025 12:57:49] code 400, message Bad request version ('À\x14À')
[12/Apr/2025 12:57:49] You're accessing the development server over HTTPS, but it only supports HTTP.
Not Found: /
[12/Apr/2025 12:57:50] "GET / HTTP/1.1" 404 2308
Not Found: /login
[12/Apr/2025 12:57:50] "GET /login HTTP/1.1" 404 2341
/home/ubuntu/Chaeyeon-Lee/Toy-Project/toyproject/config/settings.py changed, reloading.
Watching for file changes with StatReloader
Performing system checks...

Exception in thread django-main-thread:
Traceback (most recent call last):
  File "/usr/lib/python3.12/threading.py", line 1075, in _bootstrap_inner
    self.run()
  File "/usr/lib/python3.12/threading.py", line 1012, in run
    self._target(*self._args, **self._kwargs)
  File "/home/ubuntu/.cache/pypoetry/virtualenvs/toyproject-i2V2OP8o-py3.12/lib/python3.12/site-packages/django/utils/autoreload.py", line 64, in wrapper
    fn(*args, **kwargs)
  File "/home/ubuntu/.cache/pypoetry/virtualenvs/toyproject-i2V2OP8o-py3.12/lib/python3.12/site-packages/django/core/management/commands/runserver.py", line 134, in inner_run
    self.check(**check_kwargs)
  File "/home/ubuntu/.cache/pypoetry/virtualenvs/toyproject-i2V2OP8o-py3.12/lib/python3.12/site-packages/django/core/management/base.py", line 569, in check
    raise SystemCheckError(msg)
django.core.management.base.SystemCheckError: SystemCheckError: System check identified some issues:

ERRORS:
?: (corsheaders.E014) Origin 'https://xaerinoo.github.io/Toy-Project' in CORS_ALLOWED_ORIGINS should not have path

System check identified 1 issue (0 silenced).
Watching for file changes with StatReloader
Performing system checks...

Exception in thread django-main-thread:
Traceback (most recent call last):
  File "/usr/lib/python3.12/threading.py", line 1075, in _bootstrap_inner
    self.run()
  File "/usr/lib/python3.12/threading.py", line 1012, in run
    self._target(*self._args, **self._kwargs)
  File "/home/ubuntu/.cache/pypoetry/virtualenvs/toyproject-i2V2OP8o-py3.12/lib/python3.12/site-packages/django/utils/autoreload.py", line 64, in wrapper
    fn(*args, **kwargs)
  File "/home/ubuntu/.cache/pypoetry/virtualenvs/toyproject-i2V2OP8o-py3.12/lib/python3.12/site-packages/django/core/management/commands/runserver.py", line 134, in inner_run
    self.check(**check_kwargs)
  File "/home/ubuntu/.cache/pypoetry/virtualenvs/toyproject-i2V2OP8o-py3.12/lib/python3.12/site-packages/django/core/management/base.py", line 569, in check
    raise SystemCheckError(msg)
django.core.management.base.SystemCheckError: SystemCheckError: System check identified some issues:

ERRORS:
?: (corsheaders.E014) Origin 'https://xaerinoo.github.io/Toy-Project' in CORS_ALLOWED_ORIGINS should not have path

System check identified 1 issue (0 silenced).
/home/ubuntu/Chaeyeon-Lee/Toy-Project/toyproject/config/settings.py changed, reloading.
Watching for file changes with StatReloader
Performing system checks...

Exception in thread django-main-thread:
Traceback (most recent call last):
  File "/usr/lib/python3.12/threading.py", line 1075, in _bootstrap_inner
    self.run()
  File "/usr/lib/python3.12/threading.py", line 1012, in run
    self._target(*self._args, **self._kwargs)
  File "/home/ubuntu/.cache/pypoetry/virtualenvs/toyproject-i2V2OP8o-py3.12/lib/python3.12/site-packages/django/utils/autoreload.py", line 64, in wrapper
    fn(*args, **kwargs)
  File "/home/ubuntu/.cache/pypoetry/virtualenvs/toyproject-i2V2OP8o-py3.12/lib/python3.12/site-packages/django/core/management/commands/runserver.py", line 134, in inner_run
    self.check(**check_kwargs)
  File "/home/ubuntu/.cache/pypoetry/virtualenvs/toyproject-i2V2OP8o-py3.12/lib/python3.12/site-packages/django/core/management/base.py", line 569, in check
    raise SystemCheckError(msg)
django.core.management.base.SystemCheckError: SystemCheckError: System check identified some issues:

ERRORS:
?: (corsheaders.E014) Origin 'https://xaerinoo.github.io/Toy-Project' in CORS_ALLOWED_ORIGINS should not have path

System check identified 1 issue (0 silenced).
/home/ubuntu/Chaeyeon-Lee/Toy-Project/toyproject/config/settings.py changed, reloading.
Watching for file changes with StatReloader
Performing system checks...

Exception in thread django-main-thread:
Traceback (most recent call last):
  File "/usr/lib/python3.12/threading.py", line 1075, in _bootstrap_inner
    self.run()
  File "/usr/lib/python3.12/threading.py", line 1012, in run
    self._target(*self._args, **self._kwargs)
  File "/home/ubuntu/.cache/pypoetry/virtualenvs/toyproject-i2V2OP8o-py3.12/lib/python3.12/site-packages/django/utils/autoreload.py", line 64, in wrapper
    fn(*args, **kwargs)
  File "/home/ubuntu/.cache/pypoetry/virtualenvs/toyproject-i2V2OP8o-py3.12/lib/python3.12/site-packages/django/core/management/commands/runserver.py", line 134, in inner_run
    self.check(**check_kwargs)
  File "/home/ubuntu/.cache/pypoetry/virtualenvs/toyproject-i2V2OP8o-py3.12/lib/python3.12/site-packages/django/core/management/base.py", line 569, in check
    raise SystemCheckError(msg)
django.core.management.base.SystemCheckError: SystemCheckError: System check identified some issues:

ERRORS:
?: (corsheaders.E014) Origin 'https://xaerinoo.github.io/Toy-Project' in CORS_ALLOWED_ORIGINS should not have path

System check identified 1 issue (0 silenced).
/home/ubuntu/Chaeyeon-Lee/Toy-Project/toyproject/config/settings.py changed, reloading.
Watching for file changes with StatReloader
Performing system checks...

Exception in thread django-main-thread:
Traceback (most recent call last):
  File "/usr/lib/python3.12/threading.py", line 1075, in _bootstrap_inner
    self.run()
  File "/usr/lib/python3.12/threading.py", line 1012, in run
    self._target(*self._args, **self._kwargs)
  File "/home/ubuntu/.cache/pypoetry/virtualenvs/toyproject-i2V2OP8o-py3.12/lib/python3.12/site-packages/django/utils/autoreload.py", line 64, in wrapper
    fn(*args, **kwargs)
  File "/home/ubuntu/.cache/pypoetry/virtualenvs/toyproject-i2V2OP8o-py3.12/lib/python3.12/site-packages/django/core/management/commands/runserver.py", line 134, in inner_run
    self.check(**check_kwargs)
  File "/home/ubuntu/.cache/pypoetry/virtualenvs/toyproject-i2V2OP8o-py3.12/lib/python3.12/site-packages/django/core/management/base.py", line 569, in check
    raise SystemCheckError(msg)
django.core.management.base.SystemCheckError: SystemCheckError: System check identified some issues:

ERRORS:
?: (corsheaders.E014) Origin 'https://xaerinoo.github.io/Toy-Project/' in CORS_ALLOWED_ORIGINS should not have path

System check identified 1 issue (0 silenced).
Watching for file changes with StatReloader
Performing system checks...

System check identified no issues (0 silenced).
April 12, 2025 - 14:28:34
Django version 5.2, using settings 'config.settings'
Starting development server at http://0.0.0.0:8000/
Quit the server with CONTROL-C.

WARNING: This is a development server. Do not use it in a production setting. Use a production WSGI or ASGI server instead.
For more information on production servers see: https://docs.djangoproject.com/en/5.2/howto/deployment/
